
# Created by Ruins mod version 17.2 Ingame Parser
# authoring Player: bpekes

# TEMPLATE PARAMETER SETTINGS:
#
# criterion expression specifying mod ids required to load template
# may include plus (AND), minus (AND NOT), comma (OR), and parentheses
# all required mods listed must be present; no prohibited mods can be
requiredMods=scp+tconstruct+environmentaltech+contenttweaker+fossil+galacticraftcore
#
# likelihood this template will be chosen relative to all others
# e.g., a weight=6 template is chosen 3X as often as one with weight=2
weight=0
#
# list of dimensions in which this template may spawn, even if generic
# one or more dimension names, separated by commas (blank = all)
dimensionsToSpawnIn=NotToSpawnAutomatically
#
# list of other biomes in which this template may spawn
# biome corresponding to directory is always assumed, listed or not
# generic templates should leave this list empty
biomesToSpawnIn=
#
# criterion expression specifying types of biome where template spawns
# this is in addition to those explicitly listed as biomesToSpawnIn
# generic templates should leave this list empty
biomeTypesToSpawnIn=
#
# list of biomes in which this template may not spawn
# takes precedence over biomeTypesToSpawnIn, but NOT biomesToSpawnIn
# should be empty if biomeTypesToSpawnIn is empty
biomesToNotSpawnIn=
#
# depth template is pushed down into the surface when built
# offset is min/max range of random additional bury depth
embed_into_distance=0
random_height_offset=0,0
#
# whitelist/blacklist of block types on which template may be built
# specify one, not both; leave the other empty (both empty = allow all)
acceptable_target_blocks=
unacceptable_target_blocks=flowing_water,water,flowing_lava,lava
#
# size of template (#layers, #rows per layer, #blocks per row)
dimensions=15,21,25
#
# max number of missing blocks allowed in surface beneath template
allowable_overhang=0
#
# depth/height limit affected by terrain leveling
# also maximum bumpiness tolerated in surface beneath template
max_leveling=2
#
# padding applied to all sides of template horizontal footprint
# expands area affected by terrain leveling (-1 = no leveling)
leveling_buffer=0
#
# do not rotate template randomly when built (1 = no rotation)
preventRotation=0
#
# treat water/lava blocks as air and protect them from rule0 (1 = yes)
preserve_water=0
preserve_lava=0
#
# minimum distance this template must have from instances of itself
uniqueMinDistance=0
#
# min/max distances this template can be from world spawn (0 = no limit)
# only applies to overworld--i.e., dimension 0
spawnMinDistance=0
spawnMaxDistance=0
#
# other template built nearby whenever this one is
# syntax: <name>;<relativeX>;<maxYdifference>;<relativeZ>[;<chance>]
# may be used more than once to specify multiple neighbors
adjoining_template=

rule1=0,100,tconstruct:slime_dirt-2
rule2=0,100,tconstruct:slime-2
rule3=0,100,tconstruct:slime_grass-8
rule4=0,100,scp:foundationfloora-0
rule5=0,100,scp:foundationexteriortop-0
rule6=0,100,IInventory;minecraft:chest;galacticraftcore:battery#{electricity:15000.0f}#0#0+galacticraftcore:battery#{electricity:15000.0f}#0#1+galacticraftcore:battery#{electricity:15000.0f}#0#2+galacticraftcore:battery#{electricity:15000.0f}#0#3+galacticraftcore:battery#{electricity:15000.0f}#0#4+galacticraftcore:battery#{electricity:15000.0f}#0#5-3
rule7=0,100,environmentaltech:erodium-0
rule8=0,100,IInventory;minecraft:chest;minecraft:gunpowder#1#0#0+minecraft:ender_pearl#1#0#2+minecraft:gold_ingot#1#0#3+minecraft:gold_ingot#1#0#7+minecraft:melon_seeds#1#0#9+minecraft:gunpowder#1#0#10+minecraft:melon_seeds#1#0#16+minecraft:ender_pearl#1#0#18+minecraft:gold_ingot#2#0#24+minecraft:gunpowder#1#0#25-3
rule9=0,100,environmentaltech:structure_frame_2-0
rule10=0,100,IInventory;minecraft:chest;galacticraftcore:oxygen_tank_heavy_full#1#0#0+galacticraftcore:oxygen_tank_heavy_full#1#0#1+galacticraftcore:oxygen_tank_heavy_full#1#0#2-3
rule11=0,100,IInventory;minecraft:chest;minecraft:bone#2#0#1+minecraft:pumpkin_seeds#1#0#2+enderio:item_material#1#9#4+minecraft:rotten_flesh#4#0#6+minecraft:pumpkin_seeds#1#0#16+minecraft:rotten_flesh#1#0#17+enderio:item_alloy_ingot#1#6#18+minecraft:rotten_flesh#1#0#19+minecraft:bone#2#0#21+minecraft:rotten_flesh#2#0#22+minecraft:bone#1#0#23-3
rule12=0,100,contenttweaker:casing_heavy-0
rule13=0,100,minecraft:carpet-14
rule14=0,100,minecraft:carpet-5
rule15=0,100,scp:sliding_door-4
rule16=0,100,tconstruct:clear_glass-0
rule17=0,100,scp:control_panel-5
rule18=0,100,scp:opaque_trapdoor-11
rule19=0,100,scp:sliding_door-0
rule20=0,100,minecraft:lever-1
rule21=0,100,galacticraftcore:basic_block_moon-4
rule22=0,100,scp:foundationexteriormiddle-0
rule23=0,100,scp:foundationceiling-0
rule24=0,100,fossil:skull_lantern-3
rule25=0,100,fossil:skull_lantern-0
rule26=0,100,fossil:skull_lantern-2
rule27=0,100,fossil:skull_lantern-1
rule28=0,100,galacticraftcore:basic_block_moon-5

layer
0,0,0,0,0,0,0,0,0,0,0,0,0,0,0,0,0,0,0,0,0,0,0,0,0
0,0,0,0,0,0,0,0,0,0,0,0,0,0,0,0,0,0,0,0,0,0,0,0,0
0,0,0,0,0,0,0,0,0,0,0,0,0,0,0,0,0,0,0,0,0,0,0,0,0
0,0,0,0,0,0,0,0,0,0,0,0,0,0,0,0,0,0,0,0,0,0,0,0,0
0,0,0,0,0,0,0,0,0,0,0,0,0,0,0,0,0,0,0,0,0,0,0,0,0
0,0,0,0,0,0,0,0,0,0,0,0,0,0,0,0,0,0,0,0,0,0,0,0,0
0,0,0,0,0,0,0,0,0,0,0,0,0,0,0,0,0,0,0,0,0,0,0,0,0
0,0,0,0,0,0,0,0,0,0,0,0,0,0,0,0,0,0,0,0,0,0,0,0,0
0,0,0,0,0,0,0,0,0,1,1,0,0,0,1,0,0,0,0,0,0,0,0,0,0
0,0,0,0,0,0,0,0,1,1,0,0,0,1,0,0,0,0,0,0,0,0,0,0,0
0,0,0,0,0,0,0,0,0,1,0,0,0,0,0,0,0,0,0,0,0,0,0,0,0
0,0,0,0,0,0,0,0,0,0,0,1,0,0,0,1,0,0,0,0,0,0,0,0,0
0,0,0,0,0,0,0,0,0,0,0,0,0,0,0,0,0,0,0,0,0,0,0,0,0
0,0,0,0,0,0,0,0,0,0,0,0,0,0,0,0,0,0,0,0,0,0,0,0,0
0,0,0,0,0,0,0,0,0,0,0,0,0,0,0,0,0,0,0,0,0,0,0,0,0
0,0,0,0,0,0,0,0,0,0,0,0,0,0,0,0,0,0,0,0,0,0,0,0,0
0,0,0,0,0,0,0,0,0,0,0,0,0,0,0,0,0,0,0,0,0,0,0,0,0
0,0,0,0,0,0,0,0,0,0,0,0,0,0,0,0,0,0,0,0,0,0,0,0,0
0,0,0,0,0,0,0,0,0,0,0,0,0,0,0,0,0,0,0,0,0,0,0,0,0
0,0,0,0,0,0,0,0,0,0,0,0,0,0,0,0,0,0,0,0,0,0,0,0,0
0,0,0,0,0,0,0,0,0,0,0,0,0,0,0,0,0,0,0,0,0,0,0,0,0
endlayer

layer
0,0,0,0,0,0,0,0,0,0,0,0,0,0,0,0,0,0,0,0,0,0,0,0,0
0,0,0,0,0,0,0,0,0,0,0,0,0,0,0,0,0,0,0,0,0,0,0,0,0
0,0,0,0,0,0,0,0,0,0,0,0,0,0,0,0,0,0,0,0,0,0,0,0,0
0,0,0,0,0,0,0,0,0,0,0,0,0,0,0,0,0,0,0,0,0,0,0,0,0
0,0,0,0,0,0,0,0,1,0,0,0,0,0,0,0,0,0,0,0,0,0,0,0,0
0,0,0,0,0,0,0,0,1,1,1,0,0,0,0,0,0,0,0,0,0,0,0,0,0
0,0,0,0,0,1,1,0,1,2,2,1,1,0,0,0,0,0,0,0,0,0,0,0,0
0,0,0,0,0,0,1,1,1,2,1,2,1,1,1,0,0,0,0,0,0,0,0,0,0
0,0,0,0,0,0,1,1,2,2,1,1,1,1,1,0,0,0,1,0,0,0,0,0,0
0,0,0,0,0,1,2,1,1,1,1,1,1,1,1,0,1,0,0,0,0,0,0,0,0
0,0,0,0,1,1,1,1,0,1,1,1,1,1,1,0,0,0,0,1,0,0,0,0,0
0,0,0,0,0,1,0,0,0,0,0,1,2,1,1,1,2,1,0,0,0,0,0,0,0
0,0,0,0,0,1,0,0,0,0,0,0,0,2,1,1,1,0,0,0,0,0,0,0,0
0,0,0,0,0,0,0,0,0,0,0,0,1,1,2,1,1,0,1,0,0,0,0,0,0
0,0,0,0,0,0,0,0,0,0,0,0,0,1,0,1,1,0,0,0,0,0,0,0,0
0,0,0,0,0,0,0,0,0,0,0,0,0,0,0,1,0,0,0,0,0,0,0,0,0
0,0,0,0,0,0,0,0,0,0,0,0,0,0,0,1,0,0,0,0,0,0,0,0,0
0,0,0,0,0,0,0,0,0,0,0,0,0,0,0,0,0,0,0,0,0,0,0,0,0
0,0,0,0,0,0,0,0,0,0,0,0,0,0,0,0,0,0,0,0,0,0,0,0,0
0,0,0,0,0,0,0,0,0,0,0,0,0,0,0,0,0,0,0,0,0,0,0,0,0
0,0,0,0,0,0,0,0,0,0,0,0,0,0,0,0,0,0,0,0,0,0,0,0,0
endlayer

layer
0,0,0,0,0,0,0,0,0,0,0,0,0,0,0,0,0,0,0,0,0,0,0,0,0
0,0,0,0,0,0,0,0,0,0,0,0,0,0,0,0,0,0,0,0,0,0,0,0,0
0,0,0,0,0,1,0,0,0,0,1,0,0,0,0,0,0,0,0,0,0,0,0,0,0
0,0,0,1,1,1,1,0,0,0,1,1,0,1,1,0,0,0,0,0,0,1,0,0,0
0,0,0,1,1,1,1,0,1,1,1,1,1,1,1,1,0,0,1,0,2,0,0,0,0
0,0,0,0,1,1,1,1,0,1,1,0,0,0,0,0,0,0,0,0,0,0,0,0,0
0,0,0,0,0,1,1,0,1,1,1,1,2,1,1,0,0,0,0,0,0,0,1,0,0
0,0,1,0,0,1,2,0,1,1,1,2,1,1,0,1,1,0,2,0,1,0,0,0,0
0,0,1,0,0,1,1,1,2,1,1,1,1,1,1,2,1,0,1,1,0,0,0,0,0
0,0,3,1,0,1,1,1,1,1,1,1,1,1,1,1,1,0,1,1,0,0,0,0,0
0,0,0,0,0,1,1,1,1,1,1,1,1,0,1,1,1,1,0,1,1,0,1,0,0
0,0,1,0,1,1,1,2,1,1,1,1,1,1,1,1,1,1,0,0,0,0,0,0,0
0,0,0,0,0,0,2,1,0,2,1,2,1,2,1,1,1,2,0,0,0,0,0,0,0
0,0,0,0,0,0,1,0,0,0,1,1,0,1,1,1,1,1,1,0,0,0,0,0,0
0,0,0,0,1,1,0,0,0,0,1,0,0,1,1,1,1,1,2,1,0,0,0,0,0
0,0,0,1,1,1,0,1,0,0,0,0,0,1,1,1,1,1,1,1,0,0,0,0,0
0,0,0,0,1,0,0,1,0,1,1,1,0,0,1,1,0,0,1,0,0,0,0,0,0
0,0,0,0,0,0,0,0,0,0,0,0,0,0,0,1,0,0,0,0,0,0,0,0,0
0,0,0,0,0,0,0,0,0,0,0,0,0,0,0,0,0,0,0,0,0,0,0,0,0
0,0,0,0,0,0,0,0,0,0,0,0,0,0,0,0,0,0,0,0,0,0,0,0,0
0,0,0,0,0,0,0,0,0,0,0,0,0,0,0,0,0,0,0,0,0,0,0,0,0
endlayer

layer
0,0,0,0,0,0,0,0,0,0,0,0,0,0,0,0,0,0,0,0,0,0,0,0,0
0,0,0,0,0,1,0,0,0,0,0,0,0,0,1,1,0,0,0,0,0,0,0,0,0
0,0,1,1,1,1,1,0,1,1,1,1,1,1,1,1,1,0,0,0,1,1,0,0,0
0,0,1,1,1,1,1,1,2,2,2,1,1,1,1,1,1,1,1,1,2,1,0,0,0
0,0,1,1,1,2,1,2,1,1,1,0,1,1,1,1,2,1,1,1,2,2,0,0,0
0,0,1,1,2,1,1,1,0,0,1,1,2,2,1,1,1,2,0,0,1,1,1,0,0
0,0,1,1,1,1,1,1,1,1,1,1,1,1,1,1,1,2,1,0,2,1,1,1,0
0,0,1,1,1,1,1,1,1,1,1,1,1,1,1,1,1,1,2,1,1,0,0,0,0
0,0,1,1,1,1,1,1,1,1,1,1,1,1,1,1,1,1,1,1,1,1,1,0,0
0,0,0,1,1,1,1,1,1,1,1,0,1,1,1,1,1,2,1,2,1,1,1,1,0
0,0,0,1,1,1,1,1,1,1,1,1,1,1,2,1,1,1,2,1,1,1,1,0,0
0,0,1,2,1,1,1,1,1,1,1,1,1,1,1,1,1,1,1,1,1,0,0,0,0
0,1,2,1,1,1,1,1,1,1,1,1,1,2,1,1,1,1,1,2,1,0,0,0,0
0,0,1,1,1,2,1,1,1,1,1,1,1,1,1,1,1,1,1,2,1,1,1,0,0
0,0,1,1,1,1,1,1,2,2,2,1,1,1,1,0,1,1,1,1,1,1,0,0,0
0,0,1,1,1,1,1,1,2,1,2,1,2,1,1,2,1,1,1,1,1,1,0,0,0
0,0,1,1,1,1,2,1,1,1,1,2,1,1,1,1,2,1,1,1,1,1,0,0,0
0,0,0,0,1,1,1,1,1,1,1,1,0,0,1,1,0,0,0,1,0,0,0,0,0
0,0,0,0,0,0,0,0,1,0,0,0,0,0,0,1,0,0,0,0,0,0,0,0,0
0,0,0,0,0,0,0,0,0,0,0,0,0,0,0,0,0,0,0,0,0,0,0,0,0
0,0,0,0,0,0,0,0,0,0,0,0,0,0,0,0,0,0,0,0,0,0,0,0,0
endlayer

layer
0,0,3,0,3,0,0,0,0,0,0,3,0,3,3,3,3,3,0,0,0,0,3,0,0
0,3,3,3,3,3,3,3,3,3,3,3,3,3,3,3,3,3,3,3,3,3,3,3,0
0,3,1,1,1,1,1,1,1,1,1,1,1,1,1,1,1,1,1,1,1,1,3,0,0
3,3,1,1,1,1,1,1,1,1,1,1,1,1,1,1,1,1,1,1,1,1,3,3,3
0,3,1,1,1,1,1,1,1,1,1,1,1,1,1,1,1,1,1,1,1,1,3,3,3
0,3,1,1,1,1,1,1,1,1,1,1,1,1,1,1,1,1,1,1,1,1,3,3,0
0,3,1,1,1,1,1,1,1,1,1,1,1,1,1,1,1,1,1,1,1,1,3,3,0
0,3,1,1,1,1,1,1,1,1,1,1,1,1,1,1,1,1,1,1,1,1,3,3,0
0,3,1,1,1,1,1,1,1,1,1,1,1,1,1,1,1,1,1,1,1,1,3,3,3
0,3,1,1,1,1,1,1,1,1,1,1,1,1,1,1,1,1,1,1,1,1,3,3,0
3,3,1,1,1,1,1,1,1,1,1,1,1,1,1,1,1,1,1,1,1,1,3,3,0
3,3,1,1,1,1,1,1,1,1,1,1,1,1,1,1,1,1,1,1,1,1,3,3,3
3,3,1,1,1,1,1,1,1,1,1,1,1,1,1,1,1,1,1,1,1,1,3,3,0
3,3,1,1,1,1,1,1,1,1,1,1,1,1,1,1,1,1,1,1,1,1,3,3,0
3,3,1,1,1,1,1,1,1,1,1,1,1,1,1,1,1,1,1,1,1,1,3,3,0
3,3,1,1,1,1,1,1,1,1,1,1,1,1,1,1,1,1,1,1,1,1,3,3,0
3,3,1,1,1,1,1,1,1,1,1,1,1,1,1,1,1,1,1,1,1,1,3,3,0
0,3,3,1,1,1,1,1,1,1,1,1,1,1,1,1,1,1,1,1,1,3,3,3,3
0,0,3,3,3,3,3,3,3,3,3,3,3,3,3,3,3,3,3,3,3,3,3,0,0
0,0,0,0,0,0,0,3,3,3,3,0,0,3,3,3,3,3,3,3,0,3,3,0,0
0,0,0,0,0,0,0,0,3,0,0,0,0,0,0,0,0,0,0,0,0,0,0,0,0
endlayer

layer
0,0,0,0,0,0,0,0,0,0,0,0,0,0,0,0,0,0,0,0,0,0,0,0,0
0,0,0,0,0,0,0,0,0,0,0,0,0,0,0,0,0,0,0,0,0,0,0,0,0
0,0,4,4,4,4,4,4,4,4,4,4,4,4,4,4,4,4,4,4,4,4,0,0,0
0,0,4,4,4,4,4,4,4,4,4,4,4,4,4,4,4,4,4,4,4,4,0,0,0
0,0,4,4,4,4,4,4,4,4,4,4,4,4,4,4,4,4,4,4,4,4,0,0,0
0,0,4,4,4,4,4,4,4,4,4,4,4,4,4,4,4,4,4,4,4,4,0,0,0
0,0,4,4,4,4,4,4,4,4,4,4,4,4,4,4,4,4,4,4,4,4,0,0,0
0,0,4,4,4,4,4,4,4,4,4,4,4,4,4,4,4,4,4,4,4,4,0,0,0
0,0,4,4,4,4,4,4,4,4,4,4,4,4,4,4,4,4,4,4,4,4,0,0,0
0,0,4,4,4,4,4,4,4,4,4,4,4,4,4,4,4,4,4,4,4,4,0,0,0
0,0,4,4,4,4,4,4,4,4,4,4,4,4,4,4,4,4,4,4,4,4,0,0,0
0,0,4,4,4,4,4,4,4,4,4,4,4,4,4,4,4,4,4,4,4,4,0,0,0
0,0,4,4,4,4,4,4,4,4,4,4,4,4,4,4,4,4,4,4,4,4,0,0,0
0,0,4,4,4,4,4,4,4,4,4,4,4,4,4,4,4,4,4,4,4,4,0,0,0
0,0,4,4,4,4,4,4,4,4,4,4,4,4,4,4,4,4,4,4,4,4,0,0,0
0,0,4,4,4,4,4,4,4,4,4,4,4,4,4,4,4,4,4,4,4,4,0,0,0
0,0,4,4,4,4,4,4,4,4,4,4,4,4,4,4,4,4,4,4,4,4,0,0,0
0,0,4,4,4,4,4,4,4,4,4,4,4,4,4,4,4,4,4,4,4,4,0,0,0
0,0,0,0,0,0,0,0,0,0,0,0,0,0,0,0,0,0,0,0,0,0,0,0,0
0,0,0,0,0,0,0,0,0,0,0,0,0,0,0,0,0,0,0,0,0,0,0,0,0
0,0,0,0,0,0,0,0,0,0,0,0,0,0,0,0,0,0,0,0,0,0,0,0,0
endlayer

layer
0,0,0,0,0,0,0,0,0,0,0,0,0,0,0,0,0,0,0,0,0,0,0,0,0
0,0,0,0,0,0,0,0,0,0,0,0,0,0,0,0,0,0,0,0,0,0,0,0,0
0,0,5,5,5,5,5,5,5,5,5,5,5,5,5,5,5,5,5,5,5,5,0,0,0
0,0,5,0,0,0,0,0,0,0,0,0,0,0,0,0,0,0,0,0,0,5,0,0,0
0,0,5,0,0,0,0,0,0,0,0,0,0,0,0,0,0,0,0,0,0,5,0,0,0
0,0,5,0,0,0,0,0,0,0,0,0,0,0,0,0,0,0,0,0,0,5,0,0,0
0,0,5,0,7,7,7,7,7,0,0,0,0,0,7,7,7,7,0,0,6,5,0,0,0
0,0,5,0,7,7,7,7,7,9,9,9,9,9,7,7,7,7,0,0,8,5,0,0,0
0,0,5,0,7,7,7,7,7,0,0,0,0,0,7,7,7,7,0,0,0,5,0,0,0
0,0,5,0,9,9,9,9,9,0,0,0,0,0,9,9,9,9,0,0,10,5,0,0,0
0,0,5,0,0,0,12,0,0,0,0,0,0,0,0,0,12,0,0,0,11,5,0,0,0
0,0,5,0,0,0,12,0,0,0,0,9,0,0,0,0,12,0,0,0,0,5,0,0,0
0,0,5,0,0,14,14,14,0,0,0,0,0,0,0,13,13,13,0,0,0,5,0,0,0
0,0,5,0,0,14,14,14,0,0,0,0,0,0,0,13,13,13,0,0,0,5,0,0,0
0,0,5,0,0,0,0,0,0,0,0,0,0,0,0,0,0,0,0,0,0,5,0,0,0
0,0,5,0,0,0,0,0,0,0,0,0,0,0,0,0,0,0,0,0,0,5,0,0,0
0,0,5,0,5,5,15,5,5,0,0,0,0,0,0,0,0,0,0,0,0,5,0,0,0
0,0,5,5,5,0,0,0,5,5,5,5,5,5,5,5,5,5,5,5,5,5,0,0,0
0,0,0,0,0,0,0,0,0,0,0,0,0,0,0,0,0,0,0,0,0,0,0,0,0
0,0,0,0,0,0,0,0,0,0,0,0,0,0,0,0,0,0,0,0,0,0,0,0,0
0,0,0,0,0,0,0,0,0,0,0,0,0,0,0,0,0,0,0,0,0,0,0,0,0
endlayer

layer
0,0,0,0,0,0,0,0,0,0,0,0,0,0,0,0,0,0,0,0,0,0,0,0,0
0,0,0,0,0,0,0,0,0,0,0,0,0,0,0,0,0,0,0,0,0,0,0,0,0
0,0,5,5,5,5,5,5,5,5,5,5,5,5,5,5,5,5,5,5,5,5,0,0,0
0,0,5,0,0,0,0,0,0,0,0,0,0,0,0,0,0,0,0,0,0,5,0,0,0
0,0,5,0,0,0,0,0,0,0,0,0,0,0,0,0,0,0,0,0,0,5,0,0,0
0,0,5,0,0,0,0,0,0,0,0,0,0,0,0,0,0,0,0,0,0,5,0,0,0
0,0,5,0,7,7,7,7,7,9,9,9,9,9,7,7,7,7,0,0,0,5,0,0,0
0,0,5,0,7,7,0,0,0,0,0,0,0,0,0,0,0,7,0,0,0,5,0,0,0
0,0,5,0,7,7,0,7,7,9,9,9,9,9,7,7,0,7,0,0,0,5,0,0,0
0,0,5,0,9,9,0,9,9,0,0,0,0,0,9,9,0,9,0,0,0,5,0,0,0
0,0,5,0,0,12,16,12,0,0,0,0,0,0,0,12,16,12,0,0,0,5,0,0,0
0,0,5,0,0,12,0,12,0,0,9,17,9,0,0,12,0,12,0,0,0,5,0,0,0
0,0,5,0,0,0,18,0,0,0,0,0,0,0,0,0,18,0,0,0,0,5,0,0,0
0,0,5,0,0,0,0,0,0,0,0,0,0,0,0,0,0,0,0,0,0,5,0,0,0
0,0,5,0,0,0,0,0,0,0,0,0,0,0,0,0,0,0,0,0,0,5,0,0,0
0,0,5,0,0,0,0,0,0,0,0,0,0,0,0,0,0,0,0,0,0,5,0,0,0
0,0,5,0,5,5,19,5,5,0,0,0,0,0,0,0,0,0,0,0,0,5,0,0,0
0,0,21,5,5,0,0,20,5,5,5,5,5,5,5,5,5,5,5,5,5,5,0,0,0
0,0,0,0,0,0,0,0,0,0,0,0,0,0,0,0,0,0,0,0,0,0,0,0,0
0,0,0,0,0,0,0,0,0,0,0,0,0,0,0,0,0,0,0,0,0,0,0,0,0
0,0,0,0,0,0,0,0,0,0,0,0,0,0,0,0,0,0,0,0,0,0,0,0,0
endlayer

layer
0,0,0,0,0,0,0,0,0,0,0,0,0,0,0,0,0,0,0,0,0,0,0,0,0
0,0,0,0,0,0,0,0,0,0,0,0,0,0,0,0,0,0,0,0,0,0,0,0,0
0,0,5,5,5,5,5,5,5,5,5,5,5,5,5,5,5,5,5,5,21,21,0,0,0
0,0,5,0,0,0,0,0,0,0,0,0,0,0,0,0,0,0,0,0,0,5,0,0,0
0,0,5,0,0,0,0,0,0,0,0,0,0,0,0,0,0,0,0,0,0,5,0,0,0
0,0,5,0,0,0,0,0,0,0,0,0,0,0,0,0,0,0,0,0,0,5,0,0,0
0,0,5,0,7,7,7,7,7,0,0,0,0,0,7,7,7,7,0,0,0,5,0,0,0
0,0,5,0,7,7,7,7,7,9,9,9,9,9,7,7,7,7,0,0,0,5,0,0,0
0,0,5,0,7,7,7,7,7,0,0,0,0,0,7,7,7,7,0,0,0,5,0,0,0
0,0,5,0,9,9,9,9,9,0,0,0,0,0,9,9,9,9,0,0,0,5,0,0,0
0,0,5,0,0,0,12,0,0,0,0,0,0,0,0,0,12,0,0,0,0,5,0,0,0
0,0,5,0,0,0,12,0,0,0,0,9,0,0,0,0,12,0,0,0,0,5,0,0,0
0,0,5,0,0,0,0,0,0,0,0,0,0,0,0,0,0,0,0,0,0,5,0,0,0
0,0,5,0,0,0,0,0,0,0,0,0,0,0,0,0,0,0,0,0,0,5,0,0,0
0,0,5,0,0,0,0,0,0,0,0,0,0,0,0,0,0,0,0,0,0,5,0,0,0
0,0,5,0,0,0,0,0,0,0,0,0,0,0,0,0,0,0,0,0,0,5,0,0,0
0,0,5,0,5,5,5,5,5,0,0,0,0,0,0,0,0,0,0,0,0,5,0,0,0
0,0,21,5,5,0,0,0,5,5,5,5,5,5,5,5,5,5,5,5,5,5,0,0,0
0,0,0,0,0,0,0,0,0,0,0,0,0,0,0,0,0,0,0,0,0,0,0,0,0
0,0,0,0,0,0,0,0,0,0,0,0,0,0,0,0,0,0,0,0,0,0,0,0,0
0,0,0,0,0,0,0,0,0,0,0,0,0,0,0,0,0,0,0,0,0,0,0,0,0
endlayer

layer
0,0,0,0,0,0,0,0,0,0,0,0,0,0,0,0,0,0,0,0,0,0,0,0,0
0,0,0,0,0,0,0,0,0,0,0,0,0,0,0,0,0,0,0,0,0,0,0,0,0
0,0,5,5,5,5,5,5,5,5,5,5,5,5,5,5,5,5,5,21,21,21,0,0,0
0,0,5,0,0,0,0,0,0,0,0,0,0,0,0,0,0,0,0,0,0,5,0,0,0
0,0,5,0,0,0,0,0,0,0,0,0,0,0,0,0,0,0,0,0,0,21,0,0,0
0,0,5,0,0,0,0,0,0,0,0,0,0,0,0,0,0,0,0,0,0,5,0,0,0
0,0,5,0,0,0,0,0,0,0,0,0,0,0,0,0,0,0,0,0,0,5,0,0,0
0,0,5,0,0,0,0,0,0,0,0,0,0,0,0,0,0,0,0,0,0,5,0,0,0
0,0,5,0,0,0,0,0,0,0,0,0,0,0,0,0,0,0,0,0,0,5,0,0,0
0,0,5,0,0,0,0,0,0,0,0,0,0,0,0,0,0,0,0,0,0,5,0,0,0
0,0,5,0,0,0,0,0,0,0,0,0,0,0,0,0,0,0,0,0,0,5,0,0,0
0,0,5,0,0,0,0,0,0,0,0,0,0,0,0,0,0,0,0,0,0,5,0,0,0
0,0,5,0,0,0,0,0,0,0,0,0,0,0,0,0,0,0,0,0,0,5,0,0,0
0,0,5,0,0,0,0,0,0,0,0,0,0,0,0,0,0,0,0,0,0,5,0,0,0
0,0,5,0,0,0,0,0,0,0,0,0,0,0,0,0,0,0,0,0,0,5,0,0,0
0,21,5,0,0,0,0,0,0,0,0,0,0,0,0,0,0,0,0,0,0,5,0,0,0
0,0,21,0,5,5,5,5,5,0,0,0,0,0,0,0,0,0,0,0,0,5,0,0,0
0,0,21,21,5,5,5,5,5,5,5,5,5,5,5,5,5,5,5,5,5,5,0,0,0
0,0,0,0,0,0,0,0,0,0,0,0,0,0,0,0,0,0,0,0,0,0,0,0,0
0,0,0,0,0,0,0,0,0,0,0,0,0,0,0,0,0,0,0,0,0,0,0,0,0
0,0,0,0,0,0,0,0,0,0,0,0,0,0,0,0,0,0,0,0,0,0,0,0,0
endlayer

layer
0,0,0,0,0,0,0,0,0,0,0,0,0,0,0,0,0,0,0,0,0,0,0,0,0
0,0,0,0,0,0,0,0,0,0,0,0,0,0,0,0,0,0,0,0,0,0,0,0,0
0,0,5,5,5,5,5,5,5,5,5,5,5,5,5,5,5,21,21,21,21,21,0,0,0
0,0,5,0,0,0,0,0,0,0,0,0,0,0,0,0,0,0,0,0,0,21,0,0,0
0,0,5,0,0,0,0,0,0,0,0,0,0,0,0,0,0,0,0,0,0,5,21,0,0
0,0,5,0,0,0,0,0,0,0,0,0,0,0,0,0,0,0,0,0,0,5,0,0,0
0,0,5,0,0,0,0,0,0,0,0,0,0,0,0,0,0,0,0,0,0,5,0,0,0
0,0,5,0,0,0,0,0,0,0,0,0,0,0,0,0,0,0,0,0,0,5,0,0,0
0,0,5,0,0,0,0,0,0,0,0,0,0,0,0,0,0,0,0,0,0,5,0,0,0
0,0,5,0,0,0,0,0,0,0,0,0,0,0,0,0,0,0,0,0,0,5,0,0,0
0,0,5,0,0,0,0,0,0,0,0,0,0,0,0,0,0,0,0,0,0,5,0,0,0
0,0,5,0,0,0,0,0,0,0,0,0,0,0,0,0,0,0,0,0,0,5,0,0,0
0,0,5,0,0,0,0,0,0,0,0,0,0,0,0,0,0,0,0,0,0,5,0,0,0
0,0,5,0,0,0,0,0,0,0,0,0,0,0,0,0,0,0,0,0,0,5,0,0,0
0,0,5,0,0,0,0,0,0,0,0,0,0,0,0,0,0,0,0,0,0,5,0,0,0
0,21,5,0,0,0,0,0,0,0,0,0,0,0,0,0,0,0,0,0,0,5,0,0,0
0,21,21,0,0,0,0,0,0,0,0,0,0,0,0,0,0,0,0,0,0,5,0,0,0
0,0,21,21,21,5,5,5,5,5,5,5,5,5,5,5,5,5,5,5,5,5,0,0,0
0,0,21,0,0,0,0,0,0,0,0,0,0,0,0,0,0,0,0,0,0,0,0,0,0
0,0,0,0,0,0,0,0,0,0,0,0,0,0,0,0,0,0,0,0,0,0,0,0,0
0,0,0,0,0,0,0,0,0,0,0,0,0,0,0,0,0,0,0,0,0,0,0,0,0
endlayer

layer
0,0,0,0,0,0,0,0,0,0,0,0,0,0,0,0,0,0,0,0,0,0,0,0,0
0,0,0,0,0,0,0,0,0,0,0,0,0,0,0,0,0,0,0,0,21,0,0,0,0
0,0,22,22,22,22,22,22,22,22,22,22,22,22,22,22,22,22,21,21,21,21,0,0,0
0,0,22,23,23,23,23,23,23,23,23,23,23,23,23,23,23,23,23,23,23,21,0,0,0
0,0,22,23,24,23,24,24,24,24,24,24,24,24,24,24,24,24,23,24,23,22,21,0,0
0,0,22,23,23,23,23,23,23,23,23,23,23,23,23,23,23,23,21,23,23,21,0,0,0
0,0,22,23,26,23,0,0,0,0,0,0,0,0,0,0,0,0,23,25,23,22,0,0,0
0,0,22,23,26,23,0,0,0,0,0,0,0,0,0,0,0,0,23,25,23,22,0,0,0
0,0,22,23,26,23,0,0,0,0,0,0,0,0,0,0,0,0,23,25,23,22,0,0,0
0,0,22,23,26,23,0,0,0,0,0,0,0,0,0,0,0,0,23,25,23,22,0,0,0
0,0,22,23,26,23,0,0,0,0,0,0,0,0,0,0,0,0,23,25,23,22,0,0,0
0,0,22,23,26,23,0,0,0,0,0,0,0,0,0,0,0,0,23,25,23,22,0,0,0
0,0,22,23,26,23,0,0,0,0,0,0,0,0,0,0,0,0,23,25,23,22,0,0,0
0,0,22,23,26,23,0,0,0,0,0,0,0,0,0,0,0,0,23,25,23,22,0,0,0
0,21,22,23,23,23,23,23,23,23,23,23,23,23,23,23,23,23,23,23,23,22,0,0,0
0,21,22,23,27,23,27,27,27,27,27,27,27,27,27,27,27,27,23,27,23,22,0,0,0
0,21,22,23,23,23,23,23,23,23,23,23,23,23,23,23,23,23,23,23,23,22,0,0,0
0,21,21,22,21,21,21,21,22,22,22,22,22,22,22,22,22,22,22,22,22,22,0,0,0
0,0,21,21,0,0,0,0,0,0,0,0,0,0,0,0,0,0,0,0,0,0,0,0,0
0,0,0,0,0,0,0,0,0,0,0,0,0,0,0,0,0,0,0,0,0,0,0,0,0
0,0,0,0,0,0,0,0,0,0,0,0,0,0,0,0,0,0,0,0,0,0,0,0,0
endlayer

layer
0,0,0,0,0,0,0,0,0,0,0,0,0,0,0,0,0,0,0,0,0,0,0,0,0
0,0,28,28,0,0,0,28,28,28,28,28,28,28,28,0,0,0,21,21,21,0,0,0,0
0,28,28,28,28,28,28,28,28,23,23,23,23,23,23,28,28,21,21,21,21,21,0,0,0
0,28,28,28,28,21,21,28,28,28,23,23,23,23,28,21,21,21,21,21,21,21,21,0,0
0,28,28,28,21,21,21,21,21,28,28,23,23,23,28,21,21,21,21,21,21,21,0,0,0
0,0,28,21,21,21,23,23,21,21,28,23,23,28,21,23,21,21,21,28,21,21,0,0,0
0,0,28,23,21,21,21,23,23,21,28,28,28,28,21,21,23,21,21,28,21,21,0,0,0
0,28,23,23,23,21,21,21,23,21,28,28,28,28,28,28,21,21,21,28,28,28,0,0,0
0,28,23,23,23,23,21,21,21,21,23,23,28,28,28,28,21,21,21,28,28,28,28,0,0
0,28,23,23,23,23,23,21,28,23,23,23,23,23,28,21,21,21,28,28,28,23,28,0,0
0,28,23,23,23,23,21,21,28,23,23,23,23,23,21,21,21,21,28,28,23,23,28,28,0
0,28,23,23,21,21,21,21,28,21,23,23,23,23,23,23,23,21,21,28,23,23,28,28,0
0,0,28,28,21,21,21,21,28,21,21,23,23,23,28,28,21,21,28,23,23,28,28,0,0
0,0,28,21,21,21,21,21,21,21,21,23,21,28,28,28,28,28,28,23,23,28,28,0,0
0,21,21,21,21,21,21,21,21,23,23,23,21,28,28,28,28,28,23,23,23,28,28,0,0
0,21,23,23,21,21,21,23,23,23,23,21,21,28,28,28,23,23,23,23,23,28,28,0,0
0,21,23,23,23,21,21,21,23,21,21,21,28,28,28,23,23,28,23,28,23,28,28,0,0
0,0,21,21,21,21,21,0,21,28,28,28,28,28,28,28,28,28,28,28,28,28,0,0,0
0,0,0,0,0,0,0,0,21,28,28,28,28,28,28,28,28,0,0,0,0,0,0,0,0
0,0,0,0,0,0,0,0,0,0,0,0,0,0,0,0,0,0,0,0,0,0,0,0,0
0,0,0,0,0,0,0,0,0,0,0,0,0,0,0,0,0,0,0,0,0,0,0,0,0
endlayer

layer
0,0,0,0,0,0,0,0,0,0,0,0,0,0,0,0,0,0,0,0,0,0,0,0,0
0,0,0,0,0,0,0,0,0,0,0,0,0,0,0,0,0,0,0,0,21,0,0,0,0
0,0,28,0,0,0,0,0,0,28,28,28,28,28,28,0,0,0,0,21,21,21,0,0,0
0,0,28,28,0,0,0,0,0,0,28,28,28,28,0,0,0,0,0,21,21,0,0,0,0
0,0,0,28,0,0,0,0,0,0,0,28,28,28,0,0,21,21,0,0,0,0,0,0,0
0,0,0,0,0,0,21,21,0,0,0,28,28,0,0,21,21,21,21,0,0,0,0,0,0
0,0,0,28,0,0,0,21,21,21,0,0,0,0,0,0,21,0,0,0,0,0,0,0,0
0,0,28,28,28,28,0,21,21,0,0,0,0,0,0,0,0,0,0,0,0,0,0,0,0
0,0,28,28,28,28,28,0,0,0,28,28,0,0,0,0,0,0,0,0,0,0,0,0,0
0,0,28,28,28,28,28,0,0,28,28,28,28,28,0,21,0,0,0,0,0,28,0,0,0
0,0,28,28,28,28,0,0,0,28,28,28,28,28,21,21,21,0,0,0,28,28,0,0,0
0,0,28,28,0,0,0,0,0,28,28,28,28,28,21,21,21,0,0,0,28,28,0,0,0
0,0,0,0,0,0,0,0,0,0,28,28,28,28,28,0,0,0,0,28,28,28,0,0,0
0,0,0,0,0,0,0,0,0,0,21,21,28,28,28,0,0,0,0,28,28,0,0,0,0
0,0,0,0,0,0,0,0,0,21,21,21,0,28,0,0,0,0,28,28,28,0,0,0,0
0,21,21,21,21,0,0,28,28,21,21,0,0,0,0,0,28,28,28,28,28,0,0,0,0
0,0,21,21,21,0,0,0,28,0,0,0,0,0,0,28,28,0,28,28,28,0,0,0,0
0,0,0,21,0,0,0,0,0,0,0,0,0,0,0,0,0,0,0,0,0,0,0,0,0
0,0,0,0,0,0,0,0,0,0,0,0,0,0,0,0,0,0,0,0,0,0,0,0,0
0,0,0,0,0,0,0,0,0,0,0,0,0,0,0,0,0,0,0,0,0,0,0,0,0
0,0,0,0,0,0,0,0,0,0,0,0,0,0,0,0,0,0,0,0,0,0,0,0,0
endlayer

layer
0,0,0,0,0,0,0,0,0,0,0,0,0,0,0,0,0,0,0,0,0,0,0,0,0
0,0,0,0,0,0,0,0,0,0,0,0,0,0,0,0,0,0,0,0,0,0,0,0,0
0,0,0,0,0,0,0,0,0,0,0,0,0,0,0,0,0,0,0,0,0,0,0,0,0
0,0,0,0,0,0,0,0,0,0,0,0,0,0,0,0,0,0,0,0,0,0,0,0,0
0,0,0,0,0,0,0,0,0,0,0,0,0,0,0,0,0,0,0,0,0,0,0,0,0
0,0,0,0,0,0,0,0,0,0,0,0,0,0,0,0,0,0,0,0,0,0,0,0,0
0,0,0,0,0,0,0,0,0,0,0,0,0,0,0,0,0,0,0,0,0,0,0,0,0
0,0,0,0,0,0,0,0,0,0,0,0,0,0,0,0,0,0,0,0,0,0,0,0,0
0,0,0,0,28,28,0,0,0,0,0,0,0,0,0,0,0,0,0,0,0,0,0,0,0
0,0,0,28,28,28,0,0,0,0,28,28,0,0,0,0,0,0,0,0,0,0,0,0,0
0,0,0,28,0,0,0,0,0,0,0,28,28,0,0,0,0,0,0,0,0,0,0,0,0
0,0,0,0,0,0,0,0,0,0,0,28,28,0,0,0,0,0,0,0,0,0,0,0,0
0,0,0,0,0,0,0,0,0,0,0,0,0,0,0,0,0,0,0,0,0,0,0,0,0
0,0,0,0,0,0,0,0,0,0,0,0,0,0,0,0,0,0,0,0,0,0,0,0,0
0,0,0,0,0,0,0,0,0,0,0,0,0,0,0,0,0,0,0,0,0,0,0,0,0
0,0,0,0,0,0,0,0,0,0,0,0,0,0,0,0,0,0,0,0,0,0,0,0,0
0,0,0,0,0,0,0,0,0,0,0,0,0,0,0,0,0,0,0,0,0,0,0,0,0
0,0,0,0,0,0,0,0,0,0,0,0,0,0,0,0,0,0,0,0,0,0,0,0,0
0,0,0,0,0,0,0,0,0,0,0,0,0,0,0,0,0,0,0,0,0,0,0,0,0
0,0,0,0,0,0,0,0,0,0,0,0,0,0,0,0,0,0,0,0,0,0,0,0,0
0,0,0,0,0,0,0,0,0,0,0,0,0,0,0,0,0,0,0,0,0,0,0,0,0
endlayer

