
# Created by Ruins mod version 17.2 Ingame Parser
# authoring Player: bpekes

# TEMPLATE PARAMETER SETTINGS:
#
# criterion expression specifying mod ids required to load template
# may include plus (AND), minus (AND NOT), comma (OR), and parentheses
# all required mods listed must be present; no prohibited mods can be
requiredMods=tconstruct+forestry+fossil+hbm+sakura+scp+newwalls
#
# likelihood this template will be chosen relative to all others
# e.g., a weight=6 template is chosen 3X as often as one with weight=2
weight=7
#
# list of dimensions in which this template may spawn, even if generic
# one or more dimension names, separated by commas (blank = all)
dimensionsToSpawnIn=overworld
#
# list of other biomes in which this template may spawn
# biome corresponding to directory is always assumed, listed or not
# generic templates should leave this list empty
biomesToSpawnIn=
#
# criterion expression specifying types of biome where template spawns
# this is in addition to those explicitly listed as biomesToSpawnIn
# generic templates should leave this list empty
biomeTypesToSpawnIn=
#
# list of biomes in which this template may not spawn
# takes precedence over biomeTypesToSpawnIn, but NOT biomesToSpawnIn
# should be empty if biomeTypesToSpawnIn is empty
biomesToNotSpawnIn=
#
# depth template is pushed down into the surface when built
# offset is min/max range of random additional bury depth
embed_into_distance=0
random_height_offset=0,0
#
# whitelist/blacklist of block types on which template may be built
# specify one, not both; leave the other empty (both empty = allow all)
acceptable_target_blocks=
unacceptable_target_blocks=flowing_water,water,flowing_lava,lava
#
# size of template (#layers, #rows per layer, #blocks per row)
dimensions=9,15,16
#
# max number of missing blocks allowed in surface beneath template
allowable_overhang=0
#
# depth/height limit affected by terrain leveling
# also maximum bumpiness tolerated in surface beneath template
max_leveling=5
#
# padding applied to all sides of template horizontal footprint
# expands area affected by terrain leveling (-1 = no leveling)
leveling_buffer=0
#
# do not rotate template randomly when built (1 = no rotation)
preventRotation=0
#
# treat water/lava blocks as air and protect them from rule0 (1 = yes)
preserve_water=0
preserve_lava=0
#
# minimum distance this template must have from instances of itself
uniqueMinDistance=0
#
# min/max distances this template can be from world spawn (0 = no limit)
# only applies to overworld--i.e., dimension 0
spawnMinDistance=0
spawnMaxDistance=0
#
# other template built nearby whenever this one is
# syntax: <name>;<relativeX>;<maxYdifference>;<relativeZ>[;<chance>]
# may be used more than once to specify multiple neighbors
adjoining_template=

rule1=0,100,sakura:stone_lantern-0
rule2=0,100,tconstruct:brownstone-3
rule3=0,100,tconstruct:brownstone_slab-11
rule4=0,100,scp:tree_trunk-0
rule5=0,100,scp:sturdy_planks-0
rule6=0,100,sakura:tatami_tan_ns-1
rule7=0,100,hbm:brick_obsidian-0
rule8=0,100,sakura:tatami_tan_ns_half-3
rule9=0,100,minecraft:mob_spawner-0
rule10=0,100,sakura:tatami_tan_ns_half-1
rule11=0,100,newwalls:obsidian_wall-0
rule12=0,100,forestry:doors.acacia-0
rule13=0,100,hbm:crate_iron-4
rule14=0,100,forestry:doors.acacia-8
rule15=0,100,forestry:doors.acacia-9
rule16=0,100,fossil:skull_lantern-0
rule17=0,100,fossil:skull_lantern-2
rule18=0,100,tconstruct:dried_clay_slab-9
rule19=0,100,tconstruct:dried_clay_slab-1
rule20=0,100,tconstruct:brownstone_slab-3
rule21=0,100,tconstruct:dried_clay-1
rule22=0,100,tconstruct:dried_brick_stairs-5
rule23=0,100,tconstruct:brownstone_stairs_brick-5
rule24=0,100,tconstruct:dried_brick_stairs-4
rule25=0,100,tconstruct:brownstone_stairs_brick-4
rule26=0,100,tconstruct:dried_brick_stairs-0
rule27=0,100,tconstruct:brownstone_stairs_brick-0
rule28=0,100,tconstruct:dried_brick_stairs-1
rule29=0,100,tconstruct:brownstone_stairs_brick-1

layer
0,0,0,0,0,0,0,0,0,0,0,0,0,0,0,0
0,1,0,0,0,0,2,3,3,2,0,0,0,0,1,0
0,0,2,3,3,3,3,3,3,3,3,3,3,2,0,0
0,0,3,4,5,5,5,6,6,5,5,5,4,3,0,0
0,0,3,5,7,8,8,8,8,8,8,7,5,3,0,0
0,0,3,5,8,8,8,8,8,8,8,8,5,3,0,0
0,0,3,5,8,8,8,8,8,8,8,8,5,3,0,0
0,0,3,5,8,8,8,8,8,8,8,8,5,3,0,0
0,0,3,5,8,8,8,9,9,8,8,8,5,3,0,0
0,0,3,5,10,10,10,10,10,10,10,10,5,3,0,0
0,0,3,5,7,10,10,10,10,10,10,7,5,3,0,0
0,0,3,4,5,5,5,5,5,5,5,5,4,3,0,0
0,0,2,3,3,3,3,3,3,3,3,3,3,2,0,0
0,1,0,0,0,0,0,0,0,0,0,0,0,0,1,0
0,0,0,0,0,0,0,0,0,0,0,0,0,0,0,0
endlayer

layer
0,0,0,0,0,0,0,0,0,0,0,0,0,0,0,0
0,0,0,0,0,0,11,0,0,11,0,0,0,0,0,0
0,0,0,0,0,0,0,0,0,0,0,0,0,0,0,0
0,0,0,4,5,5,5,12,12,5,5,5,4,0,0,0
0,0,0,5,11,0,0,0,0,0,0,11,5,0,0,0
0,0,0,5,0,0,0,0,0,0,0,0,5,0,0,0
0,0,0,5,0,0,0,0,0,0,0,0,5,0,0,0
0,0,0,5,0,0,0,0,0,0,0,0,5,0,0,0
0,0,0,5,0,0,0,13,13,0,0,0,5,0,0,0
0,0,0,5,0,0,0,0,0,0,0,0,5,0,0,0
0,0,0,5,11,0,0,0,0,0,0,11,5,0,0,0
0,0,0,4,5,5,5,5,5,5,5,5,4,0,0,0
0,0,0,0,0,0,0,0,0,0,0,0,0,0,0,0
0,0,0,0,0,0,0,0,0,0,0,0,0,0,0,0
0,0,0,0,0,0,0,0,0,0,0,0,0,0,0,0
endlayer

layer
0,0,0,0,0,0,0,0,0,0,0,0,0,0,0,0
0,0,0,0,0,0,11,0,0,11,0,0,0,0,0,0
0,0,0,0,0,0,0,0,0,0,0,0,0,0,0,0
0,0,0,4,5,5,5,15,14,5,5,5,4,0,0,0
0,0,0,5,17,0,0,0,0,0,0,16,5,0,0,0
0,0,0,5,0,0,0,0,0,0,0,0,5,0,0,0
0,0,0,5,0,0,0,0,0,0,0,0,5,0,0,0
0,0,0,5,0,0,0,0,0,0,0,0,5,0,0,0
0,0,0,5,0,0,0,0,0,0,0,0,5,0,0,0
0,0,0,5,0,0,0,0,0,0,0,0,5,0,0,0
0,0,0,5,17,0,0,0,0,0,0,16,5,0,0,0
0,0,0,4,5,5,5,5,5,5,5,5,4,0,0,0
0,0,0,0,0,0,0,0,0,0,0,0,0,0,0,0
0,0,0,0,0,0,0,0,0,0,0,0,0,0,0,0
0,0,0,0,0,0,0,0,0,0,0,0,0,0,0,0
endlayer

layer
0,0,0,0,0,0,0,0,0,0,0,0,0,0,0,0
0,0,0,18,18,18,19,18,18,19,18,18,18,0,0,0
0,0,0,0,0,0,18,0,0,18,0,0,0,0,0,0
0,18,0,4,5,5,5,5,5,5,5,5,4,0,18,0
0,19,18,2,11,0,0,0,0,0,0,11,2,18,19,0
0,19,18,2,0,0,0,0,0,0,0,0,2,18,19,0
0,19,18,2,0,0,0,0,0,0,0,0,2,18,19,0
0,19,18,2,0,0,0,0,0,0,0,0,2,18,19,0
0,19,18,2,0,0,0,0,0,0,0,0,2,18,19,0
0,19,18,2,0,0,0,0,0,0,0,0,2,18,19,0
0,19,18,2,11,0,0,0,0,0,0,11,2,18,19,0
0,18,0,4,5,5,5,5,5,5,5,5,4,0,18,0
0,0,0,0,0,0,0,0,0,0,0,0,0,0,0,0
0,0,0,18,18,18,18,18,18,18,18,18,18,0,0,0
0,0,0,0,0,0,0,0,0,0,0,0,0,0,0,0
endlayer

layer
0,0,0,0,0,0,0,0,0,0,0,0,0,0,0,0
0,18,19,0,0,0,0,0,0,0,0,0,0,19,18,0
0,19,19,19,20,20,20,20,20,20,20,20,19,19,19,0
0,0,19,21,2,2,2,2,2,2,2,2,21,19,0,0
0,0,0,22,2,23,23,23,23,23,23,2,22,0,0,0
0,0,0,0,2,0,0,0,0,0,0,2,0,0,0,0
0,0,0,0,2,0,0,0,0,0,0,2,0,0,0,0
0,0,0,0,2,0,0,0,0,0,0,2,0,0,0,0
0,0,0,0,2,0,0,0,0,0,0,2,0,0,0,0
0,0,0,0,2,0,0,0,0,0,0,2,0,0,0,0
0,0,0,24,2,25,25,25,25,25,25,2,24,0,0,0
0,0,19,21,2,2,2,2,2,2,2,2,21,19,0,0
0,19,19,19,20,20,20,20,20,20,20,20,19,19,19,0
0,18,19,0,0,0,0,0,0,0,0,0,0,19,18,0
0,0,0,0,0,0,0,0,0,0,0,0,0,0,0,0
endlayer

layer
0,0,0,0,0,0,0,0,0,0,0,0,0,0,0,0
0,0,0,0,0,0,0,0,0,0,0,0,0,0,0,0
0,0,0,0,0,0,0,0,0,0,0,0,0,0,0,0
0,0,0,0,0,0,0,0,0,0,0,0,0,0,0,0
0,0,0,26,27,27,27,27,27,27,27,27,26,0,0,0
0,0,0,22,2,23,23,23,23,23,23,2,22,0,0,0
0,0,0,0,2,0,0,0,0,0,0,2,0,0,0,0
0,0,0,0,2,0,0,0,0,0,0,2,0,0,0,0
0,0,0,0,2,0,0,0,0,0,0,2,0,0,0,0
0,0,0,24,2,25,25,25,25,25,25,2,24,0,0,0
0,0,0,28,29,29,29,29,29,29,29,29,28,0,0,0
0,0,0,0,0,0,0,0,0,0,0,0,0,0,0,0
0,0,0,0,0,0,0,0,0,0,0,0,0,0,0,0
0,0,0,0,0,0,0,0,0,0,0,0,0,0,0,0
0,0,0,0,0,0,0,0,0,0,0,0,0,0,0,0
endlayer

layer
0,0,0,0,0,0,0,0,0,0,0,0,0,0,0,0
0,0,0,0,0,0,0,0,0,0,0,0,0,0,0,0
0,0,0,0,0,0,0,0,0,0,0,0,0,0,0,0
0,0,0,0,0,0,0,0,0,0,0,0,0,0,0,0
0,0,0,0,0,0,0,0,0,0,0,0,0,0,0,0
0,0,0,26,27,27,27,27,27,27,27,27,26,0,0,0
0,0,0,22,2,23,23,23,23,23,23,2,22,0,0,0
0,0,0,0,2,0,0,0,0,0,0,2,0,0,0,0
0,0,0,24,2,25,25,25,25,25,25,2,24,0,0,0
0,0,0,28,29,29,29,29,29,29,29,29,28,0,0,0
0,0,0,0,0,0,0,0,0,0,0,0,0,0,0,0
0,0,0,0,0,0,0,0,0,0,0,0,0,0,0,0
0,0,0,0,0,0,0,0,0,0,0,0,0,0,0,0
0,0,0,0,0,0,0,0,0,0,0,0,0,0,0,0
0,0,0,0,0,0,0,0,0,0,0,0,0,0,0,0
endlayer

layer
0,0,0,0,0,0,0,0,0,0,0,0,0,0,0,0
0,0,0,0,0,0,0,0,0,0,0,0,0,0,0,0
0,0,0,0,0,0,0,0,0,0,0,0,0,0,0,0
0,0,0,0,0,0,0,0,0,0,0,0,0,0,0,0
0,0,0,0,0,0,0,0,0,0,0,0,0,0,0,0
0,0,0,0,0,0,0,0,0,0,0,0,0,0,0,0
0,0,0,26,27,27,27,27,27,27,27,27,26,0,0,0
0,0,0,21,2,3,3,3,3,3,3,2,21,0,0,0
0,0,0,28,29,29,29,29,29,29,29,29,28,0,0,0
0,0,0,0,0,0,0,0,0,0,0,0,0,0,0,0
0,0,0,0,0,0,0,0,0,0,0,0,0,0,0,0
0,0,0,0,0,0,0,0,0,0,0,0,0,0,0,0
0,0,0,0,0,0,0,0,0,0,0,0,0,0,0,0
0,0,0,0,0,0,0,0,0,0,0,0,0,0,0,0
0,0,0,0,0,0,0,0,0,0,0,0,0,0,0,0
endlayer

layer
0,0,0,0,0,0,0,0,0,0,0,0,0,0,0,0
0,0,0,0,0,0,0,0,0,0,0,0,0,0,0,0
0,0,0,0,0,0,0,0,0,0,0,0,0,0,0,0
0,0,0,0,0,0,0,0,0,0,0,0,0,0,0,0
0,0,0,0,0,0,0,0,0,0,0,0,0,0,0,0
0,0,0,0,0,0,0,0,0,0,0,0,0,0,0,0
0,0,0,0,0,0,0,0,0,0,0,0,0,0,0,0
0,0,0,19,20,20,20,20,20,20,20,20,19,0,0,0
0,0,0,0,0,0,0,0,0,0,0,0,0,0,0,0
0,0,0,0,0,0,0,0,0,0,0,0,0,0,0,0
0,0,0,0,0,0,0,0,0,0,0,0,0,0,0,0
0,0,0,0,0,0,0,0,0,0,0,0,0,0,0,0
0,0,0,0,0,0,0,0,0,0,0,0,0,0,0,0
0,0,0,0,0,0,0,0,0,0,0,0,0,0,0,0
0,0,0,0,0,0,0,0,0,0,0,0,0,0,0,0
endlayer

