{
    "registryname": "circular_soul_farm_2",
    "localizedname": "temp",
    "requires-blueprint": true,
    "color": "E64FEE",
    "parts": [
        {
            "x": 3,
            "y": 1,
            "z": -7,
            "elements": [
                "contenttweaker:casing_ender_suppression@0"
            ]
        },
        {
            "x": 3,
            "y": 1,
            "z": -8,
            "elements": [
                "contenttweaker:casing_ender_suppression@0"
            ]
        },
        {
            "x": 4,
            "y": -1,
            "z": -7,
            "elements": [
                "environmentaltech:structure_frame_2@0"
            ]
        },
        {
            "x": 4,
            "y": -1,
            "z": -6,
            "elements": [
                "environmentaltech:structure_frame_2@0"
            ]
        },
        {
            "x": 3,
            "y": 1,
            "z": -1,
            "elements": [
                "contenttweaker:casing_ender_suppression@0"
            ]
        },
        {
            "x": 5,
            "y": 0,
            "z": -2,
            "elements": [
                "contenttweaker:casing_soul_stabilizing@0"
            ]
        },
        {
            "x": 3,
            "y": 1,
            "z": 0,
            "elements": [
                "contenttweaker:casing_ender_suppression@0"
            ]
        },
        {
            "x": 5,
            "y": 0,
            "z": -1,
            "elements": [
                "contenttweaker:casing_soul_stabilizing@0"
            ]
        },
        {
            "x": 5,
            "y": 0,
            "z": -6,
            "elements": [
                "contenttweaker:casing_soul_stabilizing@0"
            ]
        },
        {
            "x": -1,
            "y": -1,
            "z": 1,
            "elements": [
                "environmentaltech:structure_frame_2@0"
            ]
        },
        {
            "x": -4,
            "y": -1,
            "z": -2,
            "elements": [
                "environmentaltech:structure_frame_2@0"
            ]
        },
        {
            "x": 5,
            "y": 0,
            "z": -7,
            "elements": [
                "contenttweaker:casing_soul_stabilizing@0"
            ]
        },
        {
            "x": -4,
            "y": -1,
            "z": -1,
            "elements": [
                "environmentaltech:structure_frame_2@0"
            ]
        },
        {
            "x": -3,
            "y": 0,
            "z": -9,
            "elements": [
                "contenttweaker:casing_soul_stabilizing@0"
            ]
        },
        {
            "x": -2,
            "y": 1,
            "z": 0,
            "elements": [
                "contenttweaker:casing_ender_suppression@0"
            ]
        },
        {
            "x": -5,
            "y": 1,
            "z": -5,
            "elements": [
                "contenttweaker:casing_ender_suppression@0"
            ]
        },
        {
            "x": -3,
            "y": 0,
            "z": -6,
            "elements": [
                "contenttweaker:casing_soul_stabilizing@0"
            ]
        },
        {
            "x": -5,
            "y": 1,
            "z": -4,
            "elements": [
                "contenttweaker:casing_ender_suppression@0"
            ]
        },
        {
            "x": -5,
            "y": 1,
            "z": -3,
            "elements": [
                "contenttweaker:casing_ender_suppression@0"
            ]
        },
        {
            "x": -6,
            "y": 0,
            "z": -4,
            "elements": [
                "contenttweaker:casing_soul_stabilizing@0"
            ]
        },
        {
            "x": -3,
            "y": 0,
            "z": -2,
            "elements": [
                "contenttweaker:casing_soul_stabilizing@0"
            ]
        },
        {
            "x": -4,
            "y": -1,
            "z": -6,
            "elements": [
                "environmentaltech:structure_frame_2@0"
            ]
        },
        {
            "x": -6,
            "y": 0,
            "z": -5,
            "elements": [
                "contenttweaker:casing_soul_stabilizing@0"
            ]
        },
        {
            "x": -3,
            "y": 0,
            "z": 1,
            "elements": [
                "contenttweaker:casing_soul_stabilizing@0"
            ]
        },
        {
            "x": -4,
            "y": -1,
            "z": -7,
            "elements": [
                "environmentaltech:structure_frame_2@0"
            ]
        },
        {
            "x": 0,
            "y": 0,
            "z": 2,
            "elements": [
                "modularmachinery:blockenergyinputhatch@4"
            ]
        },
        {
            "x": 0,
            "y": 0,
            "z": -8,
            "elements": [
                "contenttweaker:casing_soul_stabilizing@0"
            ]
        },
        {
            "x": -2,
            "y": 1,
            "z": -8,
            "elements": [
                "contenttweaker:casing_ender_suppression@0"
            ]
        },
        {
            "x": 1,
            "y": -1,
            "z": 1,
            "elements": [
                "environmentaltech:structure_frame_2@0"
            ]
        },
        {
            "x": 0,
            "y": 0,
            "z": -10,
            "elements": [
                "contenttweaker:casing_soul_stabilizing@0"
            ]
        },
        {
            "x": -1,
            "y": 0,
            "z": -10,
            "elements": [
                "contenttweaker:casing_soul_stabilizing@0"
            ]
        },
        {
            "x": -1,
            "y": 0,
            "z": -8,
            "elements": [
                "contenttweaker:casing_soul_stabilizing@0"
            ]
        },
        {
            "x": 1,
            "y": -1,
            "z": -9,
            "elements": [
                "environmentaltech:structure_frame_2@0"
            ]
        },
        {
            "x": 1,
            "y": 1,
            "z": -9,
            "elements": [
                "contenttweaker:casing_ender_suppression@0"
            ]
        },
        {
            "x": -5,
            "y": 0,
            "z": -1,
            "elements": [
                "contenttweaker:casing_soul_stabilizing@0"
            ]
        },
        {
            "x": -5,
            "y": 0,
            "z": -2,
            "elements": [
                "contenttweaker:casing_soul_stabilizing@0"
            ]
        },
        {
            "x": -5,
            "y": 0,
            "z": -7,
            "elements": [
                "contenttweaker:casing_soul_stabilizing@0"
            ]
        },
        {
            "x": -5,
            "y": 0,
            "z": -6,
            "elements": [
                "contenttweaker:casing_soul_stabilizing@0"
            ]
        },
        {
            "x": 1,
            "y": 1,
            "z": 1,
            "elements": [
                "contenttweaker:casing_ender_suppression@0"
            ]
        },
        {
            "x": 4,
            "y": 0,
            "z": -8,
            "elements": [
                "contenttweaker:casing_soul_stabilizing@0"
            ]
        },
        {
            "x": 4,
            "y": 0,
            "z": 0,
            "elements": [
                "contenttweaker:casing_soul_stabilizing@0"
            ]
        },
        {
            "x": 4,
            "y": 0,
            "z": -5,
            "elements": [
                "contenttweaker:casing_soul_stabilizing@0"
            ]
        },
        {
            "x": 4,
            "y": 0,
            "z": -4,
            "elements": [
                "contenttweaker:casing_soul_stabilizing@0"
            ]
        },
        {
            "x": 4,
            "y": 0,
            "z": -3,
            "elements": [
                "contenttweaker:casing_soul_stabilizing@0"
            ]
        },
        {
            "x": 5,
            "y": -1,
            "z": -3,
            "elements": [
                "environmentaltech:structure_frame_2@0"
            ]
        },
        {
            "x": 5,
            "y": -1,
            "z": -5,
            "elements": [
                "environmentaltech:structure_frame_2@0"
            ]
        },
        {
            "x": 5,
            "y": -1,
            "z": -4,
            "elements": [
                "environmentaltech:structure_frame_2@0"
            ]
        },
        {
            "x": -2,
            "y": -1,
            "z": 0,
            "elements": [
                "environmentaltech:structure_frame_2@0"
            ]
        },
        {
            "x": 2,
            "y": 0,
            "z": -9,
            "elements": [
                "contenttweaker:casing_soul_stabilizing@0"
            ]
        },
        {
            "x": 2,
            "y": 0,
            "z": -7,
            "elements": [
                "contenttweaker:casing_soul_stabilizing@0"
            ]
        },
        {
            "x": -2,
            "y": -1,
            "z": -8,
            "elements": [
                "environmentaltech:structure_frame_2@0"
            ]
        },
        {
            "x": 2,
            "y": 0,
            "z": -1,
            "elements": [
                "contenttweaker:casing_soul_stabilizing@0"
            ]
        },
        {
            "x": 2,
            "y": 0,
            "z": 1,
            "elements": [
                "contenttweaker:casing_soul_stabilizing@0"
            ]
        },
        {
            "x": 1,
            "y": 0,
            "z": 2,
            "elements": [
                "modularmachinery:blockinputbus@4"
            ]
        },
        {
            "x": 1,
            "y": 0,
            "z": 0,
            "elements": [
                "modularmachinery:blockparallelcontroller@1"
            ]
        },
        {
            "x": 0,
            "y": -1,
            "z": -9,
            "elements": [
                "environmentaltech:structure_frame_2@0"
            ]
        },
        {
            "x": -5,
            "y": -1,
            "z": -3,
            "elements": [
                "environmentaltech:structure_frame_2@0"
            ]
        },
        {
            "x": -2,
            "y": 0,
            "z": -9,
            "elements": [
                "contenttweaker:casing_soul_stabilizing@0"
            ]
        },
        {
            "x": 3,
            "y": -1,
            "z": -1,
            "elements": [
                "environmentaltech:structure_frame_2@0"
            ]
        },
        {
            "x": -1,
            "y": 1,
            "z": 1,
            "elements": [
                "contenttweaker:casing_ender_suppression@0"
            ]
        },
        {
            "x": 3,
            "y": -1,
            "z": 0,
            "elements": [
                "environmentaltech:structure_frame_2@0"
            ]
        },
        {
            "x": 2,
            "y": 1,
            "z": 0,
            "elements": [
                "contenttweaker:casing_ender_suppression@0"
            ]
        },
        {
            "x": 3,
            "y": -1,
            "z": -7,
            "elements": [
                "environmentaltech:structure_frame_2@0"
            ]
        },
        {
            "x": 1,
            "y": 0,
            "z": -8,
            "elements": [
                "contenttweaker:casing_soul_stabilizing@0"
            ]
        },
        {
            "x": 3,
            "y": -1,
            "z": -8,
            "elements": [
                "environmentaltech:structure_frame_2@0"
            ]
        },
        {
            "x": -1,
            "y": 1,
            "z": -9,
            "elements": [
                "contenttweaker:casing_ender_suppression@0"
            ]
        },
        {
            "x": 1,
            "y": 0,
            "z": -10,
            "elements": [
                "contenttweaker:casing_soul_stabilizing@0"
            ]
        },
        {
            "x": 4,
            "y": 1,
            "z": -6,
            "elements": [
                "contenttweaker:casing_ender_suppression@0"
            ]
        },
        {
            "x": -2,
            "y": 0,
            "z": 1,
            "elements": [
                "contenttweaker:casing_soul_stabilizing@0"
            ]
        },
        {
            "x": 4,
            "y": 1,
            "z": -2,
            "elements": [
                "contenttweaker:casing_ender_suppression@0"
            ]
        },
        {
            "x": 4,
            "y": 1,
            "z": -1,
            "elements": [
                "contenttweaker:casing_ender_suppression@0"
            ]
        },
        {
            "x": -4,
            "y": 1,
            "z": -7,
            "elements": [
                "contenttweaker:casing_ender_suppression@0"
            ]
        },
        {
            "x": -4,
            "y": 1,
            "z": -6,
            "elements": [
                "contenttweaker:casing_ender_suppression@0"
            ]
        },
        {
            "x": -2,
            "y": 0,
            "z": -7,
            "elements": [
                "contenttweaker:casing_soul_stabilizing@0"
            ]
        },
        {
            "x": -2,
            "y": 0,
            "z": -1,
            "elements": [
                "contenttweaker:casing_soul_stabilizing@0"
            ]
        },
        {
            "x": -4,
            "y": 1,
            "z": -2,
            "elements": [
                "contenttweaker:casing_ender_suppression@0"
            ]
        },
        {
            "x": -5,
            "y": -1,
            "z": -4,
            "elements": [
                "environmentaltech:structure_frame_2@0"
            ]
        },
        {
            "x": -4,
            "y": 1,
            "z": -1,
            "elements": [
                "contenttweaker:casing_ender_suppression@0"
            ]
        },
        {
            "x": -5,
            "y": -1,
            "z": -5,
            "elements": [
                "environmentaltech:structure_frame_2@0"
            ]
        },
        {
            "x": 0,
            "y": -1,
            "z": 1,
            "elements": [
                "environmentaltech:structure_frame_2@0"
            ]
        },
        {
            "x": -3,
            "y": 1,
            "z": -1,
            "elements": [
                "contenttweaker:casing_ender_suppression@0"
            ]
        },
        {
            "x": -3,
            "y": 1,
            "z": 0,
            "elements": [
                "contenttweaker:casing_ender_suppression@0"
            ]
        },
        {
            "x": 6,
            "y": 0,
            "z": -3,
            "elements": [
                "contenttweaker:casing_soul_stabilizing@0"
            ]
        },
        {
            "x": -3,
            "y": 1,
            "z": -7,
            "elements": [
                "contenttweaker:casing_ender_suppression@0"
            ]
        },
        {
            "x": 6,
            "y": 0,
            "z": -4,
            "elements": [
                "contenttweaker:casing_soul_stabilizing@0"
            ]
        },
        {
            "x": 6,
            "y": 0,
            "z": -5,
            "elements": [
                "contenttweaker:casing_soul_stabilizing@0"
            ]
        },
        {
            "x": 4,
            "y": 1,
            "z": -7,
            "elements": [
                "contenttweaker:casing_ender_suppression@0"
            ]
        },
        {
            "x": -1,
            "y": 0,
            "z": 2,
            "elements": [
                "modularmachinery:blockoutputbus@4"
            ]
        },
        {
            "x": 5,
            "y": 1,
            "z": -4,
            "elements": [
                "contenttweaker:casing_ender_suppression@0"
            ]
        },
        {
            "x": -3,
            "y": 1,
            "z": -8,
            "elements": [
                "contenttweaker:casing_ender_suppression@0"
            ]
        },
        {
            "x": 5,
            "y": 1,
            "z": -5,
            "elements": [
                "contenttweaker:casing_ender_suppression@0"
            ]
        },
        {
            "x": -1,
            "y": 0,
            "z": 0,
            "elements": [
                "contenttweaker:casing_soul_stabilizing@0"
            ]
        },
        {
            "x": 5,
            "y": 1,
            "z": -3,
            "elements": [
                "contenttweaker:casing_ender_suppression@0"
            ]
        },
        {
            "x": 3,
            "y": 0,
            "z": -2,
            "elements": [
                "contenttweaker:casing_soul_stabilizing@0"
            ]
        },
        {
            "x": 3,
            "y": 0,
            "z": 1,
            "elements": [
                "contenttweaker:casing_soul_stabilizing@0"
            ]
        },
        {
            "x": 2,
            "y": -1,
            "z": -8,
            "elements": [
                "environmentaltech:structure_frame_2@0"
            ]
        },
        {
            "x": 2,
            "y": -1,
            "z": 0,
            "elements": [
                "environmentaltech:structure_frame_2@0"
            ]
        },
        {
            "x": 0,
            "y": 1,
            "z": -9,
            "elements": [
                "contenttweaker:casing_ender_suppression@0"
            ]
        },
        {
            "x": 2,
            "y": 1,
            "z": -8,
            "elements": [
                "contenttweaker:casing_ender_suppression@0"
            ]
        },
        {
            "x": -4,
            "y": 0,
            "z": 0,
            "elements": [
                "contenttweaker:casing_soul_stabilizing@0"
            ]
        },
        {
            "x": -6,
            "y": 0,
            "z": -3,
            "elements": [
                "contenttweaker:casing_soul_stabilizing@0"
            ]
        },
        {
            "x": -4,
            "y": 0,
            "z": -3,
            "elements": [
                "contenttweaker:casing_soul_stabilizing@0"
            ]
        },
        {
            "x": -4,
            "y": 0,
            "z": -5,
            "elements": [
                "contenttweaker:casing_soul_stabilizing@0"
            ]
        },
        {
            "x": -1,
            "y": -1,
            "z": -9,
            "elements": [
                "environmentaltech:structure_frame_2@0"
            ]
        },
        {
            "x": -4,
            "y": 0,
            "z": -4,
            "elements": [
                "contenttweaker:casing_soul_stabilizing@0"
            ]
        },
        {
            "x": -3,
            "y": -1,
            "z": -8,
            "elements": [
                "environmentaltech:structure_frame_2@0"
            ]
        },
        {
            "x": -3,
            "y": -1,
            "z": -7,
            "elements": [
                "environmentaltech:structure_frame_2@0"
            ]
        },
        {
            "x": -3,
            "y": -1,
            "z": -1,
            "elements": [
                "environmentaltech:structure_frame_2@0"
            ]
        },
        {
            "x": 3,
            "y": 0,
            "z": -9,
            "elements": [
                "contenttweaker:casing_soul_stabilizing@0"
            ]
        },
        {
            "x": -3,
            "y": -1,
            "z": 0,
            "elements": [
                "environmentaltech:structure_frame_2@0"
            ]
        },
        {
            "x": 3,
            "y": 0,
            "z": -6,
            "elements": [
                "contenttweaker:casing_soul_stabilizing@0"
            ]
        },
        {
            "x": 0,
            "y": 1,
            "z": 1,
            "elements": [
                "contenttweaker:casing_ender_suppression@0"
            ]
        },
        {
            "x": 4,
            "y": -1,
            "z": -2,
            "elements": [
                "environmentaltech:structure_frame_2@0"
            ]
        },
        {
            "x": -4,
            "y": 0,
            "z": -8,
            "elements": [
                "contenttweaker:casing_soul_stabilizing@0"
            ]
        },
        {
            "x": 4,
            "y": -1,
            "z": -1,
            "elements": [
                "environmentaltech:structure_frame_2@0"
            ]
        }
    ]}