
# Created by Ruins mod version 17.2 Ingame Parser
# authoring Player: bpekes

# TEMPLATE PARAMETER SETTINGS:
#
# criterion expression specifying mod ids required to load template
# may include plus (AND), minus (AND NOT), comma (OR), and parentheses
# all required mods listed must be present; no prohibited mods can be
requiredMods=scp+abyssalcraft+galacticraftcore+tconstruct
#
# likelihood this template will be chosen relative to all others
# e.g., a weight=6 template is chosen 3X as often as one with weight=2
weight=15
#
# list of dimensions in which this template may spawn, even if generic
# one or more dimension names, separated by commas (blank = all)
dimensionsToSpawnIn=overworld
#
# list of other biomes in which this template may spawn
# biome corresponding to directory is always assumed, listed or not
# generic templates should leave this list empty
biomesToSpawnIn=
#
# criterion expression specifying types of biome where template spawns
# this is in addition to those explicitly listed as biomesToSpawnIn
# generic templates should leave this list empty
biomeTypesToSpawnIn=
#
# list of biomes in which this template may not spawn
# takes precedence over biomeTypesToSpawnIn, but NOT biomesToSpawnIn
# should be empty if biomeTypesToSpawnIn is empty
biomesToNotSpawnIn=
#
# depth template is pushed down into the surface when built
# offset is min/max range of random additional bury depth
embed_into_distance=2
random_height_offset=0,0
#
# whitelist/blacklist of block types on which template may be built
# specify one, not both; leave the other empty (both empty = allow all)
acceptable_target_blocks=
unacceptable_target_blocks=flowing_water,water,flowing_lava,lava
#
# size of template (#layers, #rows per layer, #blocks per row)
dimensions=20,11,11
#
# max number of missing blocks allowed in surface beneath template
allowable_overhang=5
#
# depth/height limit affected by terrain leveling
# also maximum bumpiness tolerated in surface beneath template
max_leveling=2
#
# padding applied to all sides of template horizontal footprint
# expands area affected by terrain leveling (-1 = no leveling)
leveling_buffer=0
#
# do not rotate template randomly when built (1 = no rotation)
preventRotation=0
#
# treat water/lava blocks as air and protect them from rule0 (1 = yes)
preserve_water=0
preserve_lava=0
#
# minimum distance this template must have from instances of itself
uniqueMinDistance=0
#
# min/max distances this template can be from world spawn (0 = no limit)
# only applies to overworld--i.e., dimension 0
spawnMinDistance=0
spawnMaxDistance=0
#
# other template built nearby whenever this one is
# syntax: <name>;<relativeX>;<maxYdifference>;<relativeZ>[;<chance>]
# may be used more than once to specify multiple neighbors
adjoining_template=

rule1=0,100,scp:grate-0
rule2=0,100,scp:foundationexteriorbottom-0
rule3=0,100,scp:pd-0
rule4=0,100,scp:foundationexteriormiddle-0
rule5=0,100,scp:sliding_door-5
rule6=0,100,scp:reinforcedwalla-0
rule7=0,100,scp:re_wall_a_stairs-0
rule8=0,100,scp:foundationexteriortop-0
rule9=0,100,scp:sliding_door-1
rule10=0,100,scp:heavy_button-3
rule11=0,100,galacticraftcore:bright_air-0
rule12=0,100,scp:reinforcedwallb-0
rule13=0,100,scp:pdfloor-0
rule14=0,100,tconstruct:stone_ladder-5
rule15=0,100,abyssalcraft:statue-3
rule16=0,100,scp:living_room_lamp-1
rule17=0,100,scp:living_room_lamp-0
rule18=0,100,scp:reinforcedwallc-0
rule19=0,100,scp:foundationceiling-0
rule20=0,100,scp:pdcorridora-0
rule21=0,100,abyssalcraft:statue-0
rule22=0,100,minecraft:redstone_wire-0
rule23=0,100,IInventory;minecraft:chest;abyssalcraft:energypedestal#{PotEnergy:0.0f}#0#0+abyssalcraft:statetransformer#1#0#1+abyssalcraft:energydepositioner#1#0#2-5
rule24=0,100,scp:card_reader-1
rule25=0,100,minecraft:unpowered_repeater-1
rule26=0,100,minecraft:unpowered_repeater-2
rule27=2,100,minecraft:piston_head-10
rule28=0,100,minecraft:sticky_piston-10
rule29=2,100,minecraft:redstone_torch-1
rule30=0,100,scp:pdcorridorc-0
rule31=0,100,scp:heavy_button-1
rule32=0,100,scp:pdcorridorb-0
rule33=0,100,galacticraftcore:arclamp-4
rule34=0,100,galacticraftcore:arclamp-3

layer
1,1,1,1,1,1,1,1,1,1,1
1,1,1,1,1,1,1,1,1,1,1
1,1,1,1,1,1,1,1,1,1,1
1,1,1,1,1,1,1,1,1,1,1
1,1,1,1,1,1,1,1,1,1,1
1,1,1,1,1,1,1,1,1,1,1
1,1,1,1,1,1,1,1,1,1,1
1,1,1,1,1,1,1,1,1,1,1
1,1,1,1,1,1,1,1,1,1,1
1,1,1,1,1,1,1,1,1,1,1
1,1,1,1,1,1,1,1,1,1,1
endlayer

layer
2,2,2,2,2,2,2,2,2,2,2
2,2,2,2,2,3,2,2,2,2,2
2,2,2,2,3,3,3,2,2,2,2
2,2,2,2,3,3,3,2,2,2,2
2,2,2,2,2,2,2,2,2,2,2
2,2,2,2,2,2,2,2,2,2,2
2,2,2,2,2,2,2,2,2,2,2
2,2,2,2,2,2,2,2,2,2,2
2,2,2,2,2,2,2,2,2,2,2
2,2,2,2,2,2,2,2,2,2,2
2,2,2,2,2,2,2,2,2,2,2
endlayer

layer
4,4,4,4,4,5,4,4,4,4,4
4,3,3,3,3,0,3,3,3,3,4
4,3,3,3,6,0,6,3,3,3,4
4,3,3,3,6,7,6,3,3,3,4
4,3,3,3,3,3,3,3,3,3,4
4,3,3,3,3,3,3,3,3,3,4
4,3,3,3,3,3,3,3,3,3,4
4,3,3,3,3,3,3,3,3,3,4
4,3,3,3,3,3,3,3,3,3,4
4,3,3,3,3,3,3,3,3,3,4
4,4,4,4,4,4,4,4,4,4,4
endlayer

layer
8,8,8,8,8,9,8,8,8,8,8
8,3,3,3,3,10,3,3,3,3,8
8,3,3,3,6,0,6,3,3,3,8
8,3,3,3,6,11,6,3,3,3,8
8,3,3,3,6,7,6,3,3,3,8
8,3,3,3,3,3,3,3,3,3,8
8,3,3,3,3,3,3,3,3,3,8
8,3,3,3,3,3,3,3,3,3,8
8,3,3,3,3,3,3,3,3,3,8
8,3,3,3,3,3,3,3,3,3,8
8,8,8,8,8,8,8,8,8,8,8
endlayer

layer
8,8,8,8,8,8,8,8,8,8,8
8,3,3,3,3,3,3,3,3,3,8
8,3,12,12,6,0,6,12,12,3,8
8,3,12,12,6,11,6,12,12,3,8
8,3,12,12,6,11,6,12,12,3,8
8,3,12,12,6,7,6,12,12,3,8
8,3,12,12,12,12,12,12,12,3,8
8,3,12,12,12,13,12,12,12,3,8
8,3,12,12,12,12,12,12,12,3,8
8,3,3,3,3,3,3,3,3,3,8
8,8,8,8,8,8,8,8,8,8,8
endlayer

layer
8,8,8,8,8,8,8,8,8,8,8
8,3,3,3,3,3,3,3,3,3,8
8,3,6,6,6,6,6,6,6,3,8
8,3,6,11,11,14,11,11,6,3,8
8,3,6,11,11,0,11,11,6,3,8
8,3,6,11,11,11,11,11,6,3,8
8,3,6,11,11,11,11,11,6,3,8
8,3,6,0,15,16,15,0,6,3,8
8,3,6,6,6,6,6,6,6,3,8
8,3,3,3,3,3,3,3,3,3,8
8,8,8,8,8,8,8,8,8,8,8
endlayer

layer
8,8,8,8,8,8,8,8,8,8,8
8,3,3,3,3,3,3,3,3,3,8
8,3,6,6,6,6,6,6,6,3,8
8,3,6,11,11,14,11,11,6,3,8
8,3,6,11,0,0,0,11,6,3,8
8,3,6,11,0,0,0,11,6,3,8
8,3,6,11,0,11,0,11,6,3,8
8,3,6,11,11,17,11,11,6,3,8
8,3,6,6,6,6,6,6,6,3,8
8,3,3,3,3,3,3,3,3,3,8
8,8,8,8,8,8,8,8,8,8,8
endlayer

layer
8,8,8,8,8,8,8,8,8,8,8
8,3,3,3,3,3,3,3,3,3,8
8,3,18,18,18,18,18,18,18,3,8
8,3,18,11,11,14,11,11,18,3,8
8,3,18,11,0,0,0,11,18,3,8
8,3,18,11,0,0,0,11,18,3,8
8,3,18,11,0,0,0,11,18,3,8
8,3,18,11,11,11,11,11,18,3,8
8,3,18,18,18,18,18,18,18,3,8
8,3,3,3,3,3,3,3,3,3,8
8,8,8,8,8,8,8,8,8,8,8
endlayer

layer
8,8,8,8,8,8,8,8,8,8,8
8,3,3,3,3,3,3,3,3,3,8
8,3,6,6,6,6,6,6,6,3,8
8,3,6,11,11,14,11,11,6,3,8
8,3,6,11,0,0,0,11,6,3,8
8,3,6,11,0,0,0,11,6,3,8
8,3,6,11,0,0,0,11,6,3,8
8,3,6,11,11,11,11,11,6,3,8
8,3,6,6,6,6,6,6,6,3,8
8,3,3,3,3,3,3,3,3,3,8
8,8,8,8,8,8,8,8,8,8,8
endlayer

layer
8,8,8,8,8,8,8,8,8,8,8
8,3,3,3,3,3,3,3,3,3,8
8,3,6,6,6,6,6,6,6,3,8
8,3,6,11,11,14,11,11,6,3,8
8,3,6,11,11,11,11,11,6,3,8
8,3,6,11,11,11,11,11,6,3,8
8,3,6,11,11,11,11,11,6,3,8
8,3,6,11,11,11,11,11,6,3,8
8,3,6,6,6,6,6,6,6,3,8
8,3,3,3,3,3,3,3,3,3,8
8,8,8,8,8,8,8,8,8,8,8
endlayer

layer
8,8,8,8,8,8,8,8,8,8,8
8,3,3,3,3,3,3,3,3,3,8
8,3,18,18,18,18,18,18,18,3,8
8,3,18,19,19,14,19,19,18,3,8
8,3,18,19,19,19,19,19,18,3,8
8,3,18,19,19,19,19,19,18,3,8
8,3,18,19,19,19,19,19,18,3,8
8,3,18,19,19,19,19,19,18,3,8
8,3,18,18,18,18,18,18,18,3,8
8,3,3,3,3,3,3,3,3,3,8
8,8,8,8,8,8,8,8,8,8,8
endlayer

layer
8,8,8,8,8,8,8,8,8,8,8
8,3,3,3,3,3,3,3,3,3,8
8,3,6,6,6,6,6,6,6,3,8
8,3,6,12,12,14,12,12,6,3,8
8,3,6,12,12,12,12,12,6,3,8
8,3,6,12,12,12,12,12,6,3,8
8,3,6,12,12,12,12,12,6,3,8
8,3,6,12,12,12,12,12,6,3,8
8,3,6,6,6,6,6,6,6,3,8
8,3,3,3,3,3,3,3,3,3,8
8,8,8,8,8,8,8,8,8,8,8
endlayer

layer
8,8,8,8,8,8,8,8,8,8,8
8,20,20,20,20,20,20,20,20,20,8
8,20,6,6,20,21,20,6,6,20,8
8,20,6,6,20,11,20,6,6,20,8
8,20,22,20,11,11,20,20,20,20,8
8,20,25,20,24,11,20,23,11,20,8
8,20,6,26,20,11,20,11,11,20,8
8,20,29,28,27,6,11,11,11,20,8
8,20,0,0,20,11,11,11,11,20,8
8,20,20,20,20,20,20,20,20,20,8
8,8,8,8,8,8,8,8,8,8,8
endlayer

layer
8,8,8,8,8,8,8,8,8,8,8
8,30,30,30,30,30,30,30,30,30,8
8,30,6,6,30,11,30,6,6,30,8
8,30,22,6,30,11,30,6,22,30,8
8,30,0,30,11,11,30,30,30,30,8
8,30,0,30,11,11,30,11,31,30,8
8,30,0,0,30,11,30,11,11,30,8
8,30,6,28,27,6,11,0,11,30,8
8,30,0,0,30,11,11,11,11,30,8
8,30,30,30,30,30,30,30,30,30,8
8,8,8,8,8,8,8,8,8,8,8
endlayer

layer
8,8,8,8,8,8,8,8,8,8,8
8,32,32,32,32,32,32,32,32,32,8
8,32,22,6,32,33,32,6,22,32,8
8,32,0,6,32,11,32,6,0,32,8
8,32,0,32,11,11,32,32,32,32,8
8,32,0,32,11,11,32,0,11,32,8
8,32,0,0,32,32,32,11,11,32,8
8,32,0,0,32,32,11,0,11,32,8
8,32,0,0,32,11,11,11,11,32,8
8,32,32,32,32,32,32,32,32,32,8
8,8,8,8,8,8,8,8,8,8,8
endlayer

layer
8,8,8,8,8,8,8,8,8,8,8
8,32,32,32,32,32,32,32,32,32,8
8,32,0,22,32,32,32,22,0,32,8
8,32,0,6,32,32,32,6,0,32,8
8,32,0,32,32,32,32,32,32,32,8
8,32,0,32,32,32,32,0,11,32,8
8,32,0,0,32,32,32,11,11,32,8
8,32,0,0,32,32,11,11,11,32,8
8,32,0,0,32,34,11,11,11,32,8
8,32,32,32,32,32,32,32,32,32,8
8,8,8,8,8,8,8,8,8,8,8
endlayer

layer
8,8,8,8,8,8,8,8,8,8,8
8,32,32,32,32,32,32,32,32,32,8
8,32,0,0,0,0,0,0,0,32,8
8,32,0,22,6,6,6,22,0,32,8
8,32,0,0,0,0,32,32,32,32,8
8,32,0,0,0,0,32,32,32,32,8
8,32,0,0,0,32,32,32,32,32,8
8,32,0,0,32,32,32,32,32,32,8
8,32,0,0,32,32,32,32,32,32,8
8,32,32,32,32,32,32,32,32,32,8
8,8,8,8,8,8,8,8,8,8,8
endlayer

layer
8,8,8,8,8,8,8,8,8,8,8
8,32,32,32,32,32,32,32,32,32,8
8,32,0,0,0,0,0,0,0,32,8
8,32,0,0,22,26,22,0,0,32,8
8,32,0,0,0,0,0,0,0,32,8
8,32,0,0,0,0,0,0,0,32,8
8,32,0,0,0,0,0,0,0,32,8
8,32,0,0,0,0,0,0,0,32,8
8,32,0,0,0,0,0,0,0,32,8
8,32,32,32,32,32,32,32,32,32,8
8,8,8,8,8,8,8,8,8,8,8
endlayer

layer
4,4,4,4,4,4,4,4,4,4,4
4,32,32,32,32,32,32,32,32,32,4
4,32,32,32,32,32,32,32,32,32,4
4,32,32,32,32,32,32,32,32,32,4
4,32,32,32,32,32,32,32,32,32,4
4,32,32,32,32,32,32,32,32,32,4
4,32,32,32,32,32,32,32,32,32,4
4,32,32,32,32,32,32,32,32,32,4
4,32,32,32,32,32,32,32,32,32,4
4,32,32,32,32,32,32,32,32,32,4
4,4,4,4,4,4,4,4,4,4,4
endlayer

layer
19,19,19,19,19,19,19,19,19,19,19
19,19,19,19,19,19,19,19,19,19,19
19,19,19,19,19,19,19,19,19,19,19
19,19,19,19,19,19,19,19,19,19,19
19,19,19,19,19,19,19,19,19,19,19
19,19,19,19,19,19,19,19,19,19,19
19,19,19,19,19,19,19,19,19,19,19
19,19,19,19,19,19,19,19,19,19,19
19,19,19,19,19,19,19,19,19,19,19
19,19,19,19,19,19,19,19,19,19,19
19,19,19,19,19,19,19,19,19,19,19
endlayer

